2019-12-19 00:27:31,779 ERROR: Exception on /user/paladin [GET] [in /Users/yutong/Flask_Mega_Project/venv/lib/python3.7/site-packages/flask/app.py:1891]
Traceback (most recent call last):
  File "/Users/yutong/Flask_Mega_Project/venv/lib/python3.7/site-packages/flask/app.py", line 2446, in wsgi_app
    response = self.full_dispatch_request()
  File "/Users/yutong/Flask_Mega_Project/venv/lib/python3.7/site-packages/flask/app.py", line 1951, in full_dispatch_request
    rv = self.handle_user_exception(e)
  File "/Users/yutong/Flask_Mega_Project/venv/lib/python3.7/site-packages/flask/app.py", line 1820, in handle_user_exception
    reraise(exc_type, exc_value, tb)
  File "/Users/yutong/Flask_Mega_Project/venv/lib/python3.7/site-packages/flask/_compat.py", line 39, in reraise
    raise value
  File "/Users/yutong/Flask_Mega_Project/venv/lib/python3.7/site-packages/flask/app.py", line 1949, in full_dispatch_request
    rv = self.dispatch_request()
  File "/Users/yutong/Flask_Mega_Project/venv/lib/python3.7/site-packages/flask/app.py", line 1935, in dispatch_request
    return self.view_functions[rule.endpoint](**req.view_args)
  File "/Users/yutong/Flask_Mega_Project/venv/lib/python3.7/site-packages/flask_login/utils.py", line 261, in decorated_view
    return func(*args, **kwargs)
  File "/Users/yutong/Flask_Mega_Project/app/routes.py", line 136, in user
    posts = user.posts.order_by(Post.timestamp.desc()).paginate(
  File "/Users/yutong/Flask_Mega_Project/venv/lib/python3.7/site-packages/flask/templating.py", line 140, in render_template
    ctx.app,
  File "/Users/yutong/Flask_Mega_Project/venv/lib/python3.7/site-packages/flask/templating.py", line 120, in _render
    rv = template.render(context)
  File "/Users/yutong/Flask_Mega_Project/venv/lib/python3.7/site-packages/jinja2/asyncsupport.py", line 76, in render
    return original_render(self, *args, **kwargs)
  File "/Users/yutong/Flask_Mega_Project/venv/lib/python3.7/site-packages/jinja2/environment.py", line 1008, in render
    return self.environment.handle_exception(exc_info, True)
  File "/Users/yutong/Flask_Mega_Project/venv/lib/python3.7/site-packages/jinja2/environment.py", line 780, in handle_exception
    reraise(exc_type, exc_value, tb)
  File "/Users/yutong/Flask_Mega_Project/venv/lib/python3.7/site-packages/jinja2/_compat.py", line 37, in reraise
    raise value.with_traceback(tb)
  File "/Users/yutong/Flask_Mega_Project/app/templates/user.html", line 1, in top-level template code
    {% extends "base.html" %}
  File "/Users/yutong/Flask_Mega_Project/venv/lib/python3.7/site-packages/jinja2/environment.py", line 1005, in render
    return concat(self.root_render_func(self.new_context(vars)))
  File "/Users/yutong/Flask_Mega_Project/app/templates/user.html", line 14, in root
    {% if user == current_user %}
  File "/Users/yutong/Flask_Mega_Project/app/templates/base.html", line 14, in root
    <div class="navbar-header">
  File "/Users/yutong/Flask_Mega_Project/venv/lib/python3.7/site-packages/flask_bootstrap/templates/bootstrap/base.html", line 10, in root
    <meta name="viewport" content="width=device-width, initial-scale=1.0">
  File "/Users/yutong/Flask_Mega_Project/venv/lib/python3.7/site-packages/flask_bootstrap/templates/bootstrap/base.html", line 20, in block_doc
    {% block body -%}
  File "/Users/yutong/Flask_Mega_Project/venv/lib/python3.7/site-packages/flask_bootstrap/templates/bootstrap/base.html", line 39, in block_html
  File "/Users/yutong/Flask_Mega_Project/venv/lib/python3.7/site-packages/flask_bootstrap/templates/bootstrap/base.html", line 92, in block_body
  File "/Users/yutong/Flask_Mega_Project/app/templates/base.html", line 81, in block_content
  File "/Users/yutong/Flask_Mega_Project/app/templates/user.html", line 31, in block_app_content
    <span aria-hidden="true">&larr;</span> {{ _('Newer posts') }}
  File "/Users/yutong/Flask_Mega_Project/venv/lib/python3.7/site-packages/jinja2/runtime.py", line 262, in call
    return __obj(*args, **kwargs)
  File "/Users/yutong/Flask_Mega_Project/venv/lib/python3.7/site-packages/jinja2/runtime.py", line 630, in _fail_with_undefined_error
    raise self._undefined_exception(hint)
jinja2.exceptions.UndefinedError: '_' is undefined
2019-12-19 00:27:40,519 INFO: Flask Blog startup [in /Users/yutong/Flask_Mega_Project/app/__init__.py:54]
2019-12-19 00:27:44,092 ERROR: Exception on /user/paladin [GET] [in /Users/yutong/Flask_Mega_Project/venv/lib/python3.7/site-packages/flask/app.py:1891]
Traceback (most recent call last):
  File "/Users/yutong/Flask_Mega_Project/venv/lib/python3.7/site-packages/flask/app.py", line 2446, in wsgi_app
    response = self.full_dispatch_request()
  File "/Users/yutong/Flask_Mega_Project/venv/lib/python3.7/site-packages/flask/app.py", line 1951, in full_dispatch_request
    rv = self.handle_user_exception(e)
  File "/Users/yutong/Flask_Mega_Project/venv/lib/python3.7/site-packages/flask/app.py", line 1820, in handle_user_exception
    reraise(exc_type, exc_value, tb)
  File "/Users/yutong/Flask_Mega_Project/venv/lib/python3.7/site-packages/flask/_compat.py", line 39, in reraise
    raise value
  File "/Users/yutong/Flask_Mega_Project/venv/lib/python3.7/site-packages/flask/app.py", line 1947, in full_dispatch_request
    rv = self.preprocess_request()
  File "/Users/yutong/Flask_Mega_Project/venv/lib/python3.7/site-packages/flask/app.py", line 2241, in preprocess_request
    rv = func()
  File "/Users/yutong/Flask_Mega_Project/app/routes.py", line 19, in before_request
    g.locale = str(get_locale())
  File "/Users/yutong/Flask_Mega_Project/venv/lib/python3.7/site-packages/flask_babel/__init__.py", line 257, in get_locale
    rv = babel.locale_selector_func()
  File "/Users/yutong/Flask_Mega_Project/app/__init__.py", line 59, in get_locale
    return request.accept_languages.best_match(app.config['LANGUAGESS'])
KeyError: 'LANGUAGESS'
2019-12-19 00:27:48,043 ERROR: Exception on /user/paladin [GET] [in /Users/yutong/Flask_Mega_Project/venv/lib/python3.7/site-packages/flask/app.py:1891]
Traceback (most recent call last):
  File "/Users/yutong/Flask_Mega_Project/venv/lib/python3.7/site-packages/flask/app.py", line 2446, in wsgi_app
    response = self.full_dispatch_request()
  File "/Users/yutong/Flask_Mega_Project/venv/lib/python3.7/site-packages/flask/app.py", line 1951, in full_dispatch_request
    rv = self.handle_user_exception(e)
  File "/Users/yutong/Flask_Mega_Project/venv/lib/python3.7/site-packages/flask/app.py", line 1820, in handle_user_exception
    reraise(exc_type, exc_value, tb)
  File "/Users/yutong/Flask_Mega_Project/venv/lib/python3.7/site-packages/flask/_compat.py", line 39, in reraise
    raise value
  File "/Users/yutong/Flask_Mega_Project/venv/lib/python3.7/site-packages/flask/app.py", line 1947, in full_dispatch_request
    rv = self.preprocess_request()
  File "/Users/yutong/Flask_Mega_Project/venv/lib/python3.7/site-packages/flask/app.py", line 2241, in preprocess_request
    rv = func()
  File "/Users/yutong/Flask_Mega_Project/app/routes.py", line 19, in before_request
    g.locale = str(get_locale())
  File "/Users/yutong/Flask_Mega_Project/venv/lib/python3.7/site-packages/flask_babel/__init__.py", line 257, in get_locale
    rv = babel.locale_selector_func()
  File "/Users/yutong/Flask_Mega_Project/app/__init__.py", line 59, in get_locale
    return request.accept_languages.best_match(app.config['LANGUAGESS'])
KeyError: 'LANGUAGESS'
2019-12-19 00:27:52,171 ERROR: Exception on / [GET] [in /Users/yutong/Flask_Mega_Project/venv/lib/python3.7/site-packages/flask/app.py:1891]
Traceback (most recent call last):
  File "/Users/yutong/Flask_Mega_Project/venv/lib/python3.7/site-packages/flask/app.py", line 2446, in wsgi_app
    response = self.full_dispatch_request()
  File "/Users/yutong/Flask_Mega_Project/venv/lib/python3.7/site-packages/flask/app.py", line 1951, in full_dispatch_request
    rv = self.handle_user_exception(e)
  File "/Users/yutong/Flask_Mega_Project/venv/lib/python3.7/site-packages/flask/app.py", line 1820, in handle_user_exception
    reraise(exc_type, exc_value, tb)
  File "/Users/yutong/Flask_Mega_Project/venv/lib/python3.7/site-packages/flask/_compat.py", line 39, in reraise
    raise value
  File "/Users/yutong/Flask_Mega_Project/venv/lib/python3.7/site-packages/flask/app.py", line 1947, in full_dispatch_request
    rv = self.preprocess_request()
  File "/Users/yutong/Flask_Mega_Project/venv/lib/python3.7/site-packages/flask/app.py", line 2241, in preprocess_request
    rv = func()
  File "/Users/yutong/Flask_Mega_Project/app/routes.py", line 19, in before_request
    g.locale = str(get_locale())
  File "/Users/yutong/Flask_Mega_Project/venv/lib/python3.7/site-packages/flask_babel/__init__.py", line 257, in get_locale
    rv = babel.locale_selector_func()
  File "/Users/yutong/Flask_Mega_Project/app/__init__.py", line 59, in get_locale
    return request.accept_languages.best_match(app.config['LANGUAGESS'])
KeyError: 'LANGUAGESS'
2019-12-19 00:28:14,032 INFO: Flask Blog startup [in /Users/yutong/Flask_Mega_Project/app/__init__.py:54]
2019-12-19 00:36:22,258 INFO: Flask Blog startup [in /Users/yutong/Flask_Mega_Project/app/__init__.py:57]
